<?xml version="1.0"?>
<robot xmlns:xacro="http://www.ros.org/wiki/xacro" >
  <!-- Description fo robot's back right shoulder -->
  <link name="back_right_shoulder">
    <inertial>
      <origin xyz="-0.00119495363353912 -0.000176809986865901 -0.0222104021426802" rpy="0 0 0" />
      <mass value="0.2" />
      <inertia  ixx="0.00012877768511419067" ixy="0" ixz="0" iyy="0.00013736101027175354" iyz="0" izz="8.861666647394517e-05" />
    </inertial>
    <visual>
      <origin xyz="0 0 0" rpy="0 0 0" />
      <geometry>
        <mesh filename="package://raredog/meshes/back_right_shoulder.STL" />
      </geometry>
      <material name="">
        <color rgba="0.752941176470588 0.752941176470588 0.752941176470588 1" />
      </material>
    </visual>
    <collision>
      <origin xyz="0 0 0" rpy="0 0 0" />
      <geometry>
        <mesh filename="package://raredog/meshes/back_right_shoulder.STL" />
      </geometry>
    </collision>
  </link>

  <joint name="back_right_shoulder_joint" type="revolute">
    <origin xyz="-0.095875 -0.070109 0.00015658" rpy="0 0 0" />
    <parent link="base_footprint" />
    <child link="back_right_shoulder" />
    <axis xyz="-1 0 0" />
    <limit lower="-2.618" upper="2.618" effort="1.5" velocity="10.5" />
    <dynamics damping="0.1" friction="0.1" />
  </joint>

  <!-- Description fo robot's back right elbow -->
  <link name="back_right_elbow">
    <inertial>
      <origin xyz="0.0530168092815066 0.000531743532156383 -0.00867531583230777" rpy="0 0 0" /> 
      <mass value="1.5" />
      <inertia  ixx="0.0005033413675505933" ixy="0" ixz="0" iyy="0.0024236232170478395" iyz="0" izz="0.002449281937235287" />
    </inertial>
    <visual>
      <origin xyz="0 0 0" rpy="0 0 0" />
      <geometry>
        <mesh filename="package://raredog/meshes/back_right_elbow.STL" />
      </geometry>
      <material name="">
        <color rgba="0.752941176470588 0.752941176470588 0.752941176470588 1" />
      </material>
    </visual>
    <collision>
      <origin xyz="0 0 0" rpy="0 0 0" />
      <geometry>
        <mesh filename="package://raredog/meshes/back_right_elbow.STL" />
      </geometry>
    </collision>
  </link>

  <joint name="back_right_elbow_joint" type="revolute">
    <origin xyz="-2.4999E-05 2.4999E-05 -0.048" rpy="0 1.5708 0" />
    <parent link="back_right_shoulder" />
    <child link="back_right_elbow" />
    <axis xyz="0 1 0" />
    <limit lower="-2.618" upper="2.618" effort="1.5" velocity="10.5" />
    <dynamics damping="0.1" friction="0.1" />
  </joint>

  <!-- Description fo robot's back right wrist -->
  <link name="back_right_wrist">
    <inertial>
      <origin xyz="-0.0501854871379641 -0.00562091408227047 -0.00139057258160866" rpy="0 0 0" />
      <mass value="0.5" />
      <inertia  ixx="0.0001375477114226939" ixy="0" ixz="0" iyy="0.0010286558412690738" iyz="0" izz="0.0010911915135605424" />
    </inertial>
    <visual>
      <origin xyz="0 0 0" rpy="0 0 0" />
      <geometry>
        <mesh filename="package://raredog/meshes/back_right_wrist.STL" />
      </geometry>
      <material name="">
        <color rgba="0.752941176470588 0.752941176470588 0.752941176470588 1" />
      </material>
    </visual>
    <collision>
      <origin xyz="0 0 0" rpy="0 0 0" />
      <geometry>
        <mesh filename="package://raredog/meshes/back_right_wrist.STL" />
      </geometry>
    </collision>
  </link>

  <joint name="back_right_wrist_joint" type="revolute">
    <origin xyz="0.106033686469265 0 0" rpy="3.14159265358979 0 3.14159265358979" />
    <parent link="back_right_elbow" />
    <child link="back_right_wrist" />
    <axis xyz="1.32856310796055E-05 0.999999999911745 0" />
    <limit lower="-2.618" upper="2.618" effort="1.5" velocity="10.5" />
    <dynamics damping="0.1" friction="0.1" />
  </joint> 

  <!-- Description fo robot's back right foott --> 
  <link name="back_right_foot" />
  
  <joint name="back_right_foot_joint" type="fixed">
    <origin xyz="-0.141702532861941 -0.0132250006870532 -0.014113048791347" rpy="0 0 0" />
    <parent link="back_right_wrist" />
    <child link="back_right_foot" />
    <axis xyz="0 0 0" />
  </joint> 
</robot>