<?xml version="1.0"?>
<robot xmlns:xacro="http://www.ros.org/wiki/xacro" >
  <!-- Description fo robot's back left shoulder -->
  <link name="back_left_shoulder">
    <inertial>
      <origin xyz="0 0 0" rpy="0 0 0" />
      <mass value="0.2" />
      <inertia  ixx="0.00012877768511419067" ixy="0" ixz="0" iyy="0.00013736101027175354" iyz="0" izz="8.861666647394517e-05" />
    </inertial>
    <visual>
      <origin xyz="0 0 0" rpy="0 0 0" />
      <geometry>
        <mesh filename="package://raredog/meshes/back_left_shoulder.STL" />
      </geometry>
      <material name="">
        <color rgba="1 1 1 1" />
      </material>
    </visual>
    <collision>
      <origin xyz="0 0 0" rpy="0 0 0" />
      <geometry>
        <mesh filename="package://raredog/meshes/back_left_shoulder.STL" />
      </geometry>
    </collision>
  </link>

  <joint name="back_left_shoulder_joint" type="revolute">
    <origin xyz="-0.0958750017732382 0.0700914250798084 0.000156578087562781" rpy="0 0 0" />
    <parent link="base_footprint" />
    <child link="back_left_shoulder" />
    <axis xyz="1 0 0" />
    <limit lower="-2.618" upper="2.618" effort="1.5" velocity="10.5" />
    <dynamics damping="0.1" friction="0.1" />
  </joint>

  <!-- Description fo robot's back left elbow -->
  <link name="back_left_elbow">
    <inertial>
      <origin xyz="0.0530168092815064 0.000531743532155682 -0.00867531583230774" rpy="0 0 0" />
      <mass value="1.5" />
      <inertia  ixx="0.0005033413675505933" ixy="0" ixz="0" iyy="0.0024236232170478395" iyz="0" izz="0.002449281937235287" />
    </inertial>
    <visual>
      <origin xyz="0 0 0" rpy="0 0 0" />
      <geometry>
        <mesh filename="package://raredog/meshes/back_left_elbow.STL" />
      </geometry>
      <material name="">
        <color rgba="0.752941176470588 0.752941176470588 0.752941176470588 1" />
      </material>
    </visual>
    <collision>
      <origin xyz="0 0 0" rpy="0 0 0" />
      <geometry>
        <mesh filename="package://raredog/meshes/back_left_elbow.STL" />
      </geometry>
    </collision>
  </link>

  <joint name="back_left_elbow_joint" type="revolute">
    <origin xyz="2.49991776781477E-05 -2.49992615339312E-05 -0.0480000005680917" rpy="0 1.5707963267949 0" />
    <parent link="back_left_shoulder" />
    <child link="back_left_elbow" />
    <axis xyz="0 0.999999999999999 0" />
    <limit lower="-2.618" upper="2.618" effort="1.5" velocity="10.5" />
    <dynamics damping="0.1" friction="0.1" />
  </joint>
  

  <!-- Description fo robot's back left wrist -->
  <link name="back_left_wrist">
    <inertial>
      <origin xyz="-0.0501854721037142 0.00562090541442317 -0.00139060398774386" rpy="0 0 0" />
      <mass value="0.5" />
      <inertia  ixx="0.0001375477114226939" ixy="0" ixz="0" iyy="0.0010286558412690738" iyz="0" izz="0.0010911915135605424" />
    </inertial>
    <visual>
      <origin xyz="0 0 0" rpy="0 0 0" />
      <geometry>
        <mesh filename="package://raredog/meshes/back_left_wrist.STL" />
      </geometry>
      <material name="">
        <color rgba="0.752941176470588 0.752941176470588 0.752941176470588 1" />
      </material>
    </visual>
    <collision>
      <origin xyz="0 0 0" rpy="0 0 0" />
      <geometry>
        <mesh filename="package://raredog/meshes/back_left_wrist.STL" />
      </geometry>
    </collision>
  </link>

  <joint name="back_left_wrist_joint" type="revolute">
    <origin xyz="0.106033686469264 0 0" rpy="3.14159265358979 0 3.14159265358979" />
    <parent link="back_left_elbow" />
    <child link="back_left_wrist" />
    <axis xyz="1.32856310796055E-05 0.999999999911745 0" />
    <limit lower="-2.618" upper="2.618" effort="1.5" velocity="10.5" />
    <dynamics damping="0.1" friction="0.1" />
  </joint>

  <!-- Description fo robot's back left foot -->
  <link name="back_left_foot" />

  <joint name="back_left_foot_joint" type="fixed">
    <origin xyz="-0.141702532861941 0.0132249986098497 -0.0141130520913157" rpy="0 0 0" />
    <parent link="back_left_wrist" />
    <child link="back_left_foot" />
    <axis xyz="0 0 0" />
  </joint> 
</robot>