<?xml version="1.0"?>
<robot xmlns:xacro="http://www.ros.org/wiki/xacro" >
  <!-- Description fo robot's front right shoulder -->
  <link name="front_right_shoulder">
    <inertial>
      <origin xyz="0.001145 0.00017681 -0.02221" rpy="0 0 0" />
      <mass value="0.2" />
      <inertia  ixx="0.00012877768511419067" ixy="0" ixz="0" iyy="0.00013736101027175354" iyz="0" izz="8.861666647394517e-05" />
    </inertial>
    <visual>
      <origin xyz="0 0 0" rpy="0 0 0" />
      <geometry>
        <mesh filename="package://raredog/meshes/front_right_shoulder.STL" />
      </geometry>
      <material name="">
        <color rgba="0.75294 0.75294 0.75294 1" />
      </material>
    </visual>
    <collision>
      <origin xyz="0 0 0" rpy="0 0 0" />
      <geometry>
        <mesh filename="package://raredog/meshes/front_right_shoulder.STL" />
      </geometry>
    </collision>
  </link>

  <joint name="front_right_shoulder_joint" type="revolute">
    <origin xyz="0.095875 -0.070091 0.00015658" rpy="0 0 0" />
    <parent link="base_footprint" />
    <child link="front_right_shoulder" />
    <axis xyz="-1 0 0" />
    <limit lower="-2.618" upper="2.618" effort="1.5" velocity="10.5" />
    <dynamics damping="0.1" friction="0.1" />
  </joint>

  <!-- Description fo robot's front right elbow -->
  <link name="front_right_elbow">
    <inertial>
      <origin xyz="0.0530208937874927 0.000531743531269779 -0.00865031751779008" rpy="0 0 0" />
      <mass value="1.5" />
      <inertia  ixx="0.0005033413675505933" ixy="0" ixz="0" iyy="0.0024236232170478395" iyz="0" izz="0.002449281937235287" />
    </inertial>
    <visual>
      <origin xyz="0 0 0" rpy="0 0 0" />
      <geometry>
        <mesh filename="package://raredog/meshes/front_right_elbow.STL" />
      </geometry>
      <material name="">
        <color rgba="0.752941176470588 0.752941176470588 0.752941176470588 1" />
      </material>
    </visual>
    <collision>
      <origin xyz="0 0 0" rpy="0 0 0" />
      <geometry>
        <mesh filename="package://raredog/meshes/front_right_elbow.STL" />
      </geometry>
    </collision>
  </link>

  <joint name="front_right_elbow_joint" type="revolute">
    <origin xyz="-2.5E-05 -2.4999E-05 -0.048" rpy="0 1.5708 0" />
    <parent link="front_right_shoulder" />
    <child link="front_right_elbow" />
    <axis xyz="0.61743 0.78662 0" />
    <limit lower="-2.618" upper="2.618" effort="1.5" velocity="10.5" />
    <dynamics damping="0.1" friction="0.1" />
  </joint>

  <!-- Description fo robot's front right wrist -->
  <link name="front_right_wrist">
    <inertial>
      <origin xyz="-0.0501854871379643 -0.00562091408227052 -0.00139057258160868" rpy="0 0 0" />
      <mass value="0.5" />
      <inertia  ixx="0.0001375477114226939" ixy="0" ixz="0" iyy="0.0010286558412690738" iyz="0" izz="0.0010911915135605424" />
    </inertial>
    <visual>
      <origin xyz="0 0 0" rpy="0 0 0" />
      <geometry>
        <mesh filename="package://raredog/meshes/front_right_wrist.STL" />
      </geometry>
      <material name="">
        <color rgba="0.752941176470588 0.752941176470588 0.752941176470588 1" />
      </material>
    </visual>
    <collision>
      <origin xyz="0 0 0" rpy="0 0 0" />
      <geometry>
        <mesh filename="package://raredog/meshes/front_right_wrist.STL" />
      </geometry>
    </collision>
  </link>
  
  <joint name="front_right_wrist_joint" type="revolute">
    <origin xyz="0.10603 0 4.9995E-05" rpy="3.1416 0 3.1416" />
    <parent link="front_right_elbow" />
    <child link="front_right_wrist" />
    <axis xyz="0 1 0" />
    <limit lower="-2.618" upper="2.618" effort="1.5" velocity="10.5" />
    <dynamics damping="0.1" friction="0.1" />
  </joint>

  <!-- Description fo robot's front right foot -->
  <link name="front_right_foot" />

  <joint name="front_right_foot_joint" type="fixed">
    <origin xyz="-0.1417 -0.013225 -0.014113" rpy="0 0 0" />
    <parent link="front_right_wrist" />
    <child link="front_right_foot" />
    <axis xyz="0 0 0" />
  </joint> 
</robot>